[07/03/2019 08:19:20] WARNING: Not Found: /favicon.ico
[07/03/2019 08:19:34] INFO: User: admin has logged in.
[07/03/2019 08:19:35] WARNING: Not Found: /app1/login/home.css
[07/03/2019 08:19:35] WARNING: Not Found: /docs/4.2/dist/js/bootstrap.bundle.min.js
[07/03/2019 08:19:35] WARNING: Not Found: /app1/login/dashboard.js
[07/03/2019 08:19:35] WARNING: Not Found: /docs/4.2/dist/js/bootstrap.bundle.min.js
[07/03/2019 08:19:35] WARNING: Not Found: /app1/login/dashboard.js
[29/05/2019 20:23:31] WARNING: Not Found: /
[29/05/2019 20:23:31] WARNING: Not Found: /favicon.ico
[29/05/2019 20:23:49] ERROR: Internal Server Error: /app1/login/
Traceback (most recent call last):
  File "/home/bartomeu/djenv/lib/python3.6/site-packages/django/db/backends/utils.py", line 85, in _execute
    return self.cursor.execute(sql, params)
  File "/home/bartomeu/djenv/lib/python3.6/site-packages/django/db/backends/sqlite3/base.py", line 296, in execute
    return Database.Cursor.execute(self, query, params)
sqlite3.OperationalError: no such column: app1_user.password

The above exception was the direct cause of the following exception:

Traceback (most recent call last):
  File "/home/bartomeu/djenv/lib/python3.6/site-packages/django/core/handlers/exception.py", line 34, in inner
    response = get_response(request)
  File "/home/bartomeu/djenv/lib/python3.6/site-packages/django/core/handlers/base.py", line 126, in _get_response
    response = self.process_exception_by_middleware(e, request)
  File "/home/bartomeu/djenv/lib/python3.6/site-packages/django/core/handlers/base.py", line 124, in _get_response
    response = wrapped_callback(request, *callback_args, **callback_kwargs)
  File "/home/bartomeu/Documents/project1/app1/views.py", line 35, in login
    user = User.objects.get(user_name=request.POST['username'])
  File "/home/bartomeu/djenv/lib/python3.6/site-packages/django/db/models/manager.py", line 82, in manager_method
    return getattr(self.get_queryset(), name)(*args, **kwargs)
  File "/home/bartomeu/djenv/lib/python3.6/site-packages/django/db/models/query.py", line 393, in get
    num = len(clone)
  File "/home/bartomeu/djenv/lib/python3.6/site-packages/django/db/models/query.py", line 250, in __len__
    self._fetch_all()
  File "/home/bartomeu/djenv/lib/python3.6/site-packages/django/db/models/query.py", line 1186, in _fetch_all
    self._result_cache = list(self._iterable_class(self))
  File "/home/bartomeu/djenv/lib/python3.6/site-packages/django/db/models/query.py", line 54, in __iter__
    results = compiler.execute_sql(chunked_fetch=self.chunked_fetch, chunk_size=self.chunk_size)
  File "/home/bartomeu/djenv/lib/python3.6/site-packages/django/db/models/sql/compiler.py", line 1065, in execute_sql
    cursor.execute(sql, params)
  File "/home/bartomeu/djenv/lib/python3.6/site-packages/django/db/backends/utils.py", line 100, in execute
    return super().execute(sql, params)
  File "/home/bartomeu/djenv/lib/python3.6/site-packages/django/db/backends/utils.py", line 68, in execute
    return self._execute_with_wrappers(sql, params, many=False, executor=self._execute)
  File "/home/bartomeu/djenv/lib/python3.6/site-packages/django/db/backends/utils.py", line 77, in _execute_with_wrappers
    return executor(sql, params, many, context)
  File "/home/bartomeu/djenv/lib/python3.6/site-packages/django/db/backends/utils.py", line 85, in _execute
    return self.cursor.execute(sql, params)
  File "/home/bartomeu/djenv/lib/python3.6/site-packages/django/db/utils.py", line 89, in __exit__
    raise dj_exc_value.with_traceback(traceback) from exc_value
  File "/home/bartomeu/djenv/lib/python3.6/site-packages/django/db/backends/utils.py", line 85, in _execute
    return self.cursor.execute(sql, params)
  File "/home/bartomeu/djenv/lib/python3.6/site-packages/django/db/backends/sqlite3/base.py", line 296, in execute
    return Database.Cursor.execute(self, query, params)
django.db.utils.OperationalError: no such column: app1_user.password
[29/05/2019 20:33:37] ERROR: There was an attempt to log in with the wrong credentials user name: admin, email: admin@gmail.com
[29/05/2019 20:37:19] WARNING: Not Found: /favicon.ico
[29/05/2019 20:37:47] INFO: User: admin has logged in.
[29/05/2019 20:37:47] WARNING: Not Found: /app1/login/home.css
[29/05/2019 20:37:47] WARNING: Not Found: /docs/4.2/dist/js/bootstrap.bundle.min.js
[29/05/2019 20:37:47] WARNING: Not Found: /app1/login/dashboard.js
[29/05/2019 20:37:47] WARNING: Not Found: /docs/4.2/dist/js/bootstrap.bundle.min.js
[29/05/2019 20:37:50] ERROR: Internal Server Error: /app1/requestProcess/
Traceback (most recent call last):
  File "/home/bartomeu/djenv/lib/python3.6/site-packages/django/core/handlers/exception.py", line 34, in inner
    response = get_response(request)
  File "/home/bartomeu/djenv/lib/python3.6/site-packages/django/core/handlers/base.py", line 126, in _get_response
    response = self.process_exception_by_middleware(e, request)
  File "/home/bartomeu/djenv/lib/python3.6/site-packages/django/core/handlers/base.py", line 124, in _get_response
    response = wrapped_callback(request, *callback_args, **callback_kwargs)
  File "/home/bartomeu/Documents/project1/app1/views.py", line 95, in request_process
    'error': False})
  File "/home/bartomeu/djenv/lib/python3.6/site-packages/django/shortcuts.py", line 36, in render
    content = loader.render_to_string(template_name, context, request, using=using)
  File "/home/bartomeu/djenv/lib/python3.6/site-packages/django/template/loader.py", line 62, in render_to_string
    return template.render(context, request)
  File "/home/bartomeu/djenv/lib/python3.6/site-packages/django/template/backends/django.py", line 61, in render
    return self.template.render(context)
  File "/home/bartomeu/djenv/lib/python3.6/site-packages/django/template/base.py", line 171, in render
    return self._render(context)
  File "/home/bartomeu/djenv/lib/python3.6/site-packages/django/template/base.py", line 163, in _render
    return self.nodelist.render(context)
  File "/home/bartomeu/djenv/lib/python3.6/site-packages/django/template/base.py", line 937, in render
    bit = node.render_annotated(context)
  File "/home/bartomeu/djenv/lib/python3.6/site-packages/django/template/base.py", line 904, in render_annotated
    return self.render(context)
  File "/home/bartomeu/djenv/lib/python3.6/site-packages/django/template/defaulttags.py", line 442, in render
    url = reverse(view_name, args=args, kwargs=kwargs, current_app=current_app)
  File "/home/bartomeu/djenv/lib/python3.6/site-packages/django/urls/base.py", line 90, in reverse
    return iri_to_uri(resolver._reverse_with_prefix(view, prefix, *args, **kwargs))
  File "/home/bartomeu/djenv/lib/python3.6/site-packages/django/urls/resolvers.py", line 622, in _reverse_with_prefix
    raise NoReverseMatch(msg)
django.urls.exceptions.NoReverseMatch: Reverse for 'post' not found. 'post' is not a valid view function or pattern name.
[29/05/2019 20:39:56] ERROR: Internal Server Error: /app1/requestProcess/
Traceback (most recent call last):
  File "/home/bartomeu/djenv/lib/python3.6/site-packages/django/core/handlers/exception.py", line 34, in inner
    response = get_response(request)
  File "/home/bartomeu/djenv/lib/python3.6/site-packages/django/core/handlers/base.py", line 126, in _get_response
    response = self.process_exception_by_middleware(e, request)
  File "/home/bartomeu/djenv/lib/python3.6/site-packages/django/core/handlers/base.py", line 124, in _get_response
    response = wrapped_callback(request, *callback_args, **callback_kwargs)
  File "/home/bartomeu/Documents/project1/app1/views.py", line 95, in request_process
    'error': False})
  File "/home/bartomeu/djenv/lib/python3.6/site-packages/django/shortcuts.py", line 36, in render
    content = loader.render_to_string(template_name, context, request, using=using)
  File "/home/bartomeu/djenv/lib/python3.6/site-packages/django/template/loader.py", line 62, in render_to_string
    return template.render(context, request)
  File "/home/bartomeu/djenv/lib/python3.6/site-packages/django/template/backends/django.py", line 61, in render
    return self.template.render(context)
  File "/home/bartomeu/djenv/lib/python3.6/site-packages/django/template/base.py", line 171, in render
    return self._render(context)
  File "/home/bartomeu/djenv/lib/python3.6/site-packages/django/template/base.py", line 163, in _render
    return self.nodelist.render(context)
  File "/home/bartomeu/djenv/lib/python3.6/site-packages/django/template/base.py", line 937, in render
    bit = node.render_annotated(context)
  File "/home/bartomeu/djenv/lib/python3.6/site-packages/django/template/base.py", line 904, in render_annotated
    return self.render(context)
  File "/home/bartomeu/djenv/lib/python3.6/site-packages/django/template/defaulttags.py", line 442, in render
    url = reverse(view_name, args=args, kwargs=kwargs, current_app=current_app)
  File "/home/bartomeu/djenv/lib/python3.6/site-packages/django/urls/base.py", line 90, in reverse
    return iri_to_uri(resolver._reverse_with_prefix(view, prefix, *args, **kwargs))
  File "/home/bartomeu/djenv/lib/python3.6/site-packages/django/urls/resolvers.py", line 622, in _reverse_with_prefix
    raise NoReverseMatch(msg)
django.urls.exceptions.NoReverseMatch: Reverse for 'post' not found. 'post' is not a valid view function or pattern name.
[29/05/2019 20:44:07] WARNING: Not Found: /favicon.ico
[29/05/2019 20:44:18] CRITICAL: User: admin tried to request a process but was an error validating the form
[29/05/2019 20:46:39] CRITICAL: User: admin tried to request a process but was an error validating the form
[29/05/2019 20:46:48] CRITICAL: User: admin tried to request a process but was an error validating the form
[29/05/2019 20:49:38] INFO: User: admin has logged in.
[29/05/2019 20:49:38] WARNING: Not Found: /docs/4.2/dist/js/bootstrap.bundle.min.js
[29/05/2019 20:49:38] WARNING: Not Found: /app1/login/dashboard.js
[29/05/2019 20:49:38] WARNING: Not Found: /app1/login/home.css
[29/05/2019 20:49:39] WARNING: Not Found: /docs/4.2/dist/js/bootstrap.bundle.min.js
[29/05/2019 20:49:39] WARNING: Not Found: /app1/login/dashboard.js
[29/05/2019 20:49:40] WARNING: Not Found: /favicon.ico
[29/05/2019 20:49:45] CRITICAL: User: admin tried to request a process but was an error validating the form
[29/05/2019 20:52:15] ERROR: Internal Server Error: /app1/requestProcess/
Traceback (most recent call last):
  File "/home/bartomeu/djenv/lib/python3.6/site-packages/django/core/handlers/exception.py", line 34, in inner
    response = get_response(request)
  File "/home/bartomeu/djenv/lib/python3.6/site-packages/django/core/handlers/base.py", line 126, in _get_response
    response = self.process_exception_by_middleware(e, request)
  File "/home/bartomeu/djenv/lib/python3.6/site-packages/django/core/handlers/base.py", line 124, in _get_response
    response = wrapped_callback(request, *callback_args, **callback_kwargs)
TypeError: request_process() missing 1 required positional argument: 'request'
[29/05/2019 20:54:02] CRITICAL: User: admin tried to request a process but was an error validating the form
[29/05/2019 20:54:02] WARNING: Not Found: /favicon.ico
[29/05/2019 20:54:08] CRITICAL: User: admin tried to request a process but was an error validating the form
[29/05/2019 20:54:49] ERROR: Internal Server Error: /app1/requestProcess/
Traceback (most recent call last):
  File "/home/bartomeu/djenv/lib/python3.6/site-packages/django/core/handlers/exception.py", line 34, in inner
    response = get_response(request)
  File "/home/bartomeu/djenv/lib/python3.6/site-packages/django/core/handlers/base.py", line 126, in _get_response
    response = self.process_exception_by_middleware(e, request)
  File "/home/bartomeu/djenv/lib/python3.6/site-packages/django/core/handlers/base.py", line 124, in _get_response
    response = wrapped_callback(request, *callback_args, **callback_kwargs)
  File "/home/bartomeu/Documents/project1/app1/views.py", line 66, in request_process
    form_class = form.get_form_class()
AttributeError: 'FileFieldForm' object has no attribute 'get_form_class'
[29/05/2019 20:54:49] WARNING: Not Found: /favicon.ico
[29/05/2019 20:55:15] CRITICAL: User: admin tried to request a process but was an error validating the form
[29/05/2019 20:55:20] CRITICAL: User: admin tried to request a process but was an error validating the form
[30/05/2019 16:35:21] WARNING: Not Found: /favicon.ico
[30/05/2019 16:35:27] INFO: User: admin has logged in.
[30/05/2019 16:35:28] WARNING: Not Found: /app1/login/home.css
[30/05/2019 16:35:28] WARNING: Not Found: /docs/4.2/dist/js/bootstrap.bundle.min.js
[30/05/2019 16:35:28] WARNING: Not Found: /app1/login/dashboard.js
[30/05/2019 16:35:28] WARNING: Not Found: /docs/4.2/dist/js/bootstrap.bundle.min.js
[30/05/2019 16:35:28] WARNING: Not Found: /app1/login/dashboard.js
[30/05/2019 16:35:28] WARNING: Not Found: /favicon.ico
[30/05/2019 16:35:32] WARNING: Not Found: /favicon.ico
[30/05/2019 16:35:41] ERROR: Internal Server Error: /app1/requestProcess/
Traceback (most recent call last):
  File "/home/bartomeu/djenv/lib/python3.6/site-packages/django/core/handlers/exception.py", line 34, in inner
    response = get_response(request)
  File "/home/bartomeu/djenv/lib/python3.6/site-packages/django/core/handlers/base.py", line 126, in _get_response
    response = self.process_exception_by_middleware(e, request)
  File "/home/bartomeu/djenv/lib/python3.6/site-packages/django/core/handlers/base.py", line 124, in _get_response
    response = wrapped_callback(request, *callback_args, **callback_kwargs)
  File "/home/bartomeu/Documents/project1/app1/views.py", line 72, in request_process
    type_of_process = form.cleaned_data['files']
AttributeError: 'FileFieldForm' object has no attribute 'cleaned_data'
[30/05/2019 16:36:02] WARNING: Not Found: /favicon.ico
[30/05/2019 16:36:04] WARNING: Not Found: /app1/requestProcess/home.css
[30/05/2019 16:36:04] WARNING: Not Found: /app1/requestProcess/dashboard.js
[30/05/2019 16:36:04] WARNING: Not Found: /docs/4.2/dist/js/bootstrap.bundle.min.js
[30/05/2019 16:36:04] WARNING: Not Found: /docs/4.2/dist/js/bootstrap.bundle.min.js
[30/05/2019 16:36:04] WARNING: Not Found: /app1/requestProcess/dashboard.js
[30/05/2019 16:36:55] WARNING: Not Found: /favicon.ico
[30/05/2019 16:38:12] WARNING: Not Found: /docs/4.2/dist/js/bootstrap.bundle.min.js
[30/05/2019 16:38:12] WARNING: Not Found: /app1/requestProcess/dashboard.js
[30/05/2019 16:38:12] WARNING: Not Found: /app1/requestProcess/home.css
[30/05/2019 16:38:12] WARNING: Not Found: /app1/requestProcess/dashboard.js
[30/05/2019 16:38:12] WARNING: Not Found: /favicon.ico
[30/05/2019 16:39:27] WARNING: Not Found: /docs/4.2/dist/js/bootstrap.bundle.min.js
[30/05/2019 16:39:27] WARNING: Not Found: /app1/requestProcess/dashboard.js
[30/05/2019 16:39:27] WARNING: Not Found: /app1/requestProcess/home.css
[30/05/2019 16:39:27] WARNING: Not Found: /app1/requestProcess/dashboard.js
[30/05/2019 16:41:23] WARNING: Not Found: /app1/requestProcess/home.css
[30/05/2019 16:41:23] WARNING: Not Found: /docs/4.2/dist/js/bootstrap.bundle.min.js
[30/05/2019 16:41:23] WARNING: Not Found: /app1/requestProcess/dashboard.js
[30/05/2019 16:41:23] WARNING: Not Found: /docs/4.2/dist/js/bootstrap.bundle.min.js
[30/05/2019 16:41:23] WARNING: Not Found: /app1/requestProcess/dashboard.js
[30/05/2019 16:42:32] WARNING: Not Found: /app1/requestProcess/home.css
[30/05/2019 16:42:32] WARNING: Not Found: /docs/4.2/dist/js/bootstrap.bundle.min.js
[30/05/2019 16:42:32] WARNING: Not Found: /app1/requestProcess/dashboard.js
[30/05/2019 16:42:32] WARNING: Not Found: /docs/4.2/dist/js/bootstrap.bundle.min.js
[30/05/2019 16:42:32] WARNING: Not Found: /app1/requestProcess/dashboard.js
[30/05/2019 16:50:16] WARNING: Not Found: /docs/4.2/dist/js/bootstrap.bundle.min.js
[30/05/2019 16:50:16] WARNING: Not Found: /app1/requestProcess/dashboard.js
[30/05/2019 16:50:16] WARNING: Not Found: /app1/requestProcess/home.css
[30/05/2019 16:50:16] WARNING: Not Found: /app1/requestProcess/dashboard.js
[30/05/2019 16:51:22] ERROR: Internal Server Error: /app1/requestProcess/
Traceback (most recent call last):
  File "/home/bartomeu/djenv/lib/python3.6/site-packages/django/core/handlers/exception.py", line 34, in inner
    response = get_response(request)
  File "/home/bartomeu/djenv/lib/python3.6/site-packages/django/core/handlers/base.py", line 126, in _get_response
    response = self.process_exception_by_middleware(e, request)
  File "/home/bartomeu/djenv/lib/python3.6/site-packages/django/core/handlers/base.py", line 124, in _get_response
    response = wrapped_callback(request, *callback_args, **callback_kwargs)
  File "/home/bartomeu/Documents/project1/app1/views.py", line 69, in request_process
    p = fs.path(files.name)
AttributeError: 'list' object has no attribute 'name'
[30/05/2019 16:52:44] ERROR: Internal Server Error: /app1/requestProcess/
Traceback (most recent call last):
  File "/home/bartomeu/djenv/lib/python3.6/site-packages/django/core/handlers/exception.py", line 34, in inner
    response = get_response(request)
  File "/home/bartomeu/djenv/lib/python3.6/site-packages/django/core/handlers/base.py", line 126, in _get_response
    response = self.process_exception_by_middleware(e, request)
  File "/home/bartomeu/djenv/lib/python3.6/site-packages/django/core/handlers/base.py", line 124, in _get_response
    response = wrapped_callback(request, *callback_args, **callback_kwargs)
  File "/home/bartomeu/Documents/project1/app1/views.py", line 66, in request_process
    files = request.FILES('file_field')
TypeError: 'MultiValueDict' object is not callable
[30/05/2019 16:53:17] ERROR: Internal Server Error: /app1/requestProcess/
Traceback (most recent call last):
  File "/home/bartomeu/djenv/lib/python3.6/site-packages/django/core/handlers/exception.py", line 34, in inner
    response = get_response(request)
  File "/home/bartomeu/djenv/lib/python3.6/site-packages/django/core/handlers/base.py", line 126, in _get_response
    response = self.process_exception_by_middleware(e, request)
  File "/home/bartomeu/djenv/lib/python3.6/site-packages/django/core/handlers/base.py", line 124, in _get_response
    response = wrapped_callback(request, *callback_args, **callback_kwargs)
  File "/home/bartomeu/Documents/project1/app1/views.py", line 71, in request_process
    f.write(files)
TypeError: write() argument must be str, not list
[30/05/2019 16:54:09] ERROR: Internal Server Error: /app1/requestProcess/
Traceback (most recent call last):
  File "/home/bartomeu/djenv/lib/python3.6/site-packages/django/core/handlers/exception.py", line 34, in inner
    response = get_response(request)
  File "/home/bartomeu/djenv/lib/python3.6/site-packages/django/core/handlers/base.py", line 126, in _get_response
    response = self.process_exception_by_middleware(e, request)
  File "/home/bartomeu/djenv/lib/python3.6/site-packages/django/core/handlers/base.py", line 124, in _get_response
    response = wrapped_callback(request, *callback_args, **callback_kwargs)
  File "/home/bartomeu/Documents/project1/app1/views.py", line 71, in request_process
    f.write(files[1])
IndexError: list index out of range
[30/05/2019 16:54:18] ERROR: Internal Server Error: /app1/requestProcess/
Traceback (most recent call last):
  File "/home/bartomeu/djenv/lib/python3.6/site-packages/django/core/handlers/exception.py", line 34, in inner
    response = get_response(request)
  File "/home/bartomeu/djenv/lib/python3.6/site-packages/django/core/handlers/base.py", line 126, in _get_response
    response = self.process_exception_by_middleware(e, request)
  File "/home/bartomeu/djenv/lib/python3.6/site-packages/django/core/handlers/base.py", line 124, in _get_response
    response = wrapped_callback(request, *callback_args, **callback_kwargs)
  File "/home/bartomeu/Documents/project1/app1/views.py", line 71, in request_process
    f.write(files[0])
IndexError: list index out of range
[30/05/2019 16:54:30] ERROR: Internal Server Error: /app1/requestProcess/
Traceback (most recent call last):
  File "/home/bartomeu/djenv/lib/python3.6/site-packages/django/core/handlers/exception.py", line 34, in inner
    response = get_response(request)
  File "/home/bartomeu/djenv/lib/python3.6/site-packages/django/core/handlers/base.py", line 126, in _get_response
    response = self.process_exception_by_middleware(e, request)
  File "/home/bartomeu/djenv/lib/python3.6/site-packages/django/core/handlers/base.py", line 124, in _get_response
    response = wrapped_callback(request, *callback_args, **callback_kwargs)
  File "/home/bartomeu/Documents/project1/app1/views.py", line 71, in request_process
    f.write(files[0])
IndexError: list index out of range
[30/05/2019 16:55:20] ERROR: Internal Server Error: /app1/requestProcess/
Traceback (most recent call last):
  File "/home/bartomeu/djenv/lib/python3.6/site-packages/django/core/handlers/exception.py", line 34, in inner
    response = get_response(request)
  File "/home/bartomeu/djenv/lib/python3.6/site-packages/django/core/handlers/base.py", line 126, in _get_response
    response = self.process_exception_by_middleware(e, request)
  File "/home/bartomeu/djenv/lib/python3.6/site-packages/django/core/handlers/base.py", line 124, in _get_response
    response = wrapped_callback(request, *callback_args, **callback_kwargs)
  File "/home/bartomeu/Documents/project1/app1/views.py", line 66, in request_process
    files = request.FILES('file_field')
TypeError: 'MultiValueDict' object is not callable
[30/05/2019 16:55:56] ERROR: Internal Server Error: /app1/requestProcess/
Traceback (most recent call last):
  File "/home/bartomeu/djenv/lib/python3.6/site-packages/django/core/handlers/exception.py", line 34, in inner
    response = get_response(request)
  File "/home/bartomeu/djenv/lib/python3.6/site-packages/django/core/handlers/base.py", line 126, in _get_response
    response = self.process_exception_by_middleware(e, request)
  File "/home/bartomeu/djenv/lib/python3.6/site-packages/django/core/handlers/base.py", line 124, in _get_response
    response = wrapped_callback(request, *callback_args, **callback_kwargs)
  File "/home/bartomeu/Documents/project1/app1/views.py", line 71, in request_process
    f.write(request.FILES.getlist('file_field'))
TypeError: write() argument must be str, not list
[30/05/2019 16:56:13] ERROR: Internal Server Error: /app1/requestProcess/
Traceback (most recent call last):
  File "/home/bartomeu/djenv/lib/python3.6/site-packages/django/core/handlers/exception.py", line 34, in inner
    response = get_response(request)
  File "/home/bartomeu/djenv/lib/python3.6/site-packages/django/core/handlers/base.py", line 126, in _get_response
    response = self.process_exception_by_middleware(e, request)
  File "/home/bartomeu/djenv/lib/python3.6/site-packages/django/core/handlers/base.py", line 124, in _get_response
    response = wrapped_callback(request, *callback_args, **callback_kwargs)
  File "/home/bartomeu/Documents/project1/app1/views.py", line 71, in request_process
    f.write(request.FILES.getlist('file_field')[0])
IndexError: list index out of range
[30/05/2019 16:57:12] WARNING: Not Found: /favicon.ico
[30/05/2019 16:57:13] ERROR: Internal Server Error: /app1/requestProcess/
Traceback (most recent call last):
  File "/home/bartomeu/djenv/lib/python3.6/site-packages/django/core/handlers/exception.py", line 34, in inner
    response = get_response(request)
  File "/home/bartomeu/djenv/lib/python3.6/site-packages/django/core/handlers/base.py", line 126, in _get_response
    response = self.process_exception_by_middleware(e, request)
  File "/home/bartomeu/djenv/lib/python3.6/site-packages/django/core/handlers/base.py", line 124, in _get_response
    response = wrapped_callback(request, *callback_args, **callback_kwargs)
  File "/home/bartomeu/Documents/project1/app1/views.py", line 71, in request_process
    f.write(str(request.FILES.getlist('file_field')[0]))
IndexError: list index out of range
[30/05/2019 16:57:13] WARNING: Not Found: /favicon.ico
[30/05/2019 16:57:23] ERROR: Internal Server Error: /app1/requestProcess/
Traceback (most recent call last):
  File "/home/bartomeu/djenv/lib/python3.6/site-packages/django/core/handlers/exception.py", line 34, in inner
    response = get_response(request)
  File "/home/bartomeu/djenv/lib/python3.6/site-packages/django/core/handlers/base.py", line 126, in _get_response
    response = self.process_exception_by_middleware(e, request)
  File "/home/bartomeu/djenv/lib/python3.6/site-packages/django/core/handlers/base.py", line 124, in _get_response
    response = wrapped_callback(request, *callback_args, **callback_kwargs)
  File "/home/bartomeu/Documents/project1/app1/views.py", line 72, in request_process
    for f in files:
NameError: name 'files' is not defined
[30/05/2019 16:58:11] ERROR: Internal Server Error: /app1/requestProcess/
Traceback (most recent call last):
  File "/home/bartomeu/djenv/lib/python3.6/site-packages/django/utils/datastructures.py", line 77, in __getitem__
    list_ = super().__getitem__(key)
KeyError: 'file_field'

During handling of the above exception, another exception occurred:

Traceback (most recent call last):
  File "/home/bartomeu/djenv/lib/python3.6/site-packages/django/core/handlers/exception.py", line 34, in inner
    response = get_response(request)
  File "/home/bartomeu/djenv/lib/python3.6/site-packages/django/core/handlers/base.py", line 126, in _get_response
    response = self.process_exception_by_middleware(e, request)
  File "/home/bartomeu/djenv/lib/python3.6/site-packages/django/core/handlers/base.py", line 124, in _get_response
    response = wrapped_callback(request, *callback_args, **callback_kwargs)
  File "/home/bartomeu/Documents/project1/app1/views.py", line 71, in request_process
    f.write(str(request.FILES['file_field']))
  File "/home/bartomeu/djenv/lib/python3.6/site-packages/django/utils/datastructures.py", line 79, in __getitem__
    raise MultiValueDictKeyError(key)
django.utils.datastructures.MultiValueDictKeyError: 'file_field'
[30/05/2019 16:59:33] ERROR: Internal Server Error: /app1/requestProcess/
Traceback (most recent call last):
  File "/home/bartomeu/djenv/lib/python3.6/site-packages/django/utils/datastructures.py", line 77, in __getitem__
    list_ = super().__getitem__(key)
KeyError: 'file_field'

During handling of the above exception, another exception occurred:

Traceback (most recent call last):
  File "/home/bartomeu/djenv/lib/python3.6/site-packages/django/core/handlers/exception.py", line 34, in inner
    response = get_response(request)
  File "/home/bartomeu/djenv/lib/python3.6/site-packages/django/core/handlers/base.py", line 126, in _get_response
    response = self.process_exception_by_middleware(e, request)
  File "/home/bartomeu/djenv/lib/python3.6/site-packages/django/core/handlers/base.py", line 124, in _get_response
    response = wrapped_callback(request, *callback_args, **callback_kwargs)
  File "/home/bartomeu/Documents/project1/app1/views.py", line 66, in request_process
    file = request.FILES['file_field']
  File "/home/bartomeu/djenv/lib/python3.6/site-packages/django/utils/datastructures.py", line 79, in __getitem__
    raise MultiValueDictKeyError(key)
django.utils.datastructures.MultiValueDictKeyError: 'file_field'
[30/05/2019 17:01:19] ERROR: Internal Server Error: /app1/requestProcess/
Traceback (most recent call last):
  File "/home/bartomeu/djenv/lib/python3.6/site-packages/django/core/handlers/exception.py", line 34, in inner
    response = get_response(request)
  File "/home/bartomeu/djenv/lib/python3.6/site-packages/django/core/handlers/base.py", line 126, in _get_response
    response = self.process_exception_by_middleware(e, request)
  File "/home/bartomeu/djenv/lib/python3.6/site-packages/django/core/handlers/base.py", line 124, in _get_response
    response = wrapped_callback(request, *callback_args, **callback_kwargs)
  File "/home/bartomeu/Documents/project1/app1/views.py", line 66, in request_process
    file = form.file_field
AttributeError: 'FileFieldForm' object has no attribute 'file_field'
[30/05/2019 17:02:08] ERROR: Internal Server Error: /app1/requestProcess/
Traceback (most recent call last):
  File "/home/bartomeu/djenv/lib/python3.6/site-packages/django/core/handlers/exception.py", line 34, in inner
    response = get_response(request)
  File "/home/bartomeu/djenv/lib/python3.6/site-packages/django/core/handlers/base.py", line 126, in _get_response
    response = self.process_exception_by_middleware(e, request)
  File "/home/bartomeu/djenv/lib/python3.6/site-packages/django/core/handlers/base.py", line 124, in _get_response
    response = wrapped_callback(request, *callback_args, **callback_kwargs)
  File "/home/bartomeu/Documents/project1/app1/views.py", line 69, in request_process
    fs.save(file.name, file)
  File "/home/bartomeu/djenv/lib/python3.6/site-packages/django/core/files/storage.py", line 49, in save
    return self._save(name, content)
  File "/home/bartomeu/djenv/lib/python3.6/site-packages/django/core/files/storage.py", line 264, in _save
    fd = os.open(full_path, flags, 0o666)
PermissionError: [Errno 13] Permission denied: '/media/file_field'
[30/05/2019 17:03:23] ERROR: Internal Server Error: /app1/requestProcess/
Traceback (most recent call last):
  File "/home/bartomeu/djenv/lib/python3.6/site-packages/django/core/handlers/exception.py", line 34, in inner
    response = get_response(request)
  File "/home/bartomeu/djenv/lib/python3.6/site-packages/django/core/handlers/base.py", line 126, in _get_response
    response = self.process_exception_by_middleware(e, request)
  File "/home/bartomeu/djenv/lib/python3.6/site-packages/django/core/handlers/base.py", line 124, in _get_response
    response = wrapped_callback(request, *callback_args, **callback_kwargs)
  File "/home/bartomeu/Documents/project1/app1/views.py", line 71, in request_process
    fs.save(file.name, file)
  File "/home/bartomeu/djenv/lib/python3.6/site-packages/django/core/files/storage.py", line 49, in save
    return self._save(name, content)
  File "/home/bartomeu/djenv/lib/python3.6/site-packages/django/core/files/storage.py", line 264, in _save
    fd = os.open(full_path, flags, 0o666)
PermissionError: [Errno 13] Permission denied: '/media/file_field'
[30/05/2019 17:04:31] ERROR: Internal Server Error: /app1/requestProcess/
Traceback (most recent call last):
  File "/home/bartomeu/djenv/lib/python3.6/site-packages/django/core/handlers/exception.py", line 34, in inner
    response = get_response(request)
  File "/home/bartomeu/djenv/lib/python3.6/site-packages/django/core/handlers/base.py", line 126, in _get_response
    response = self.process_exception_by_middleware(e, request)
  File "/home/bartomeu/djenv/lib/python3.6/site-packages/django/core/handlers/base.py", line 124, in _get_response
    response = wrapped_callback(request, *callback_args, **callback_kwargs)
  File "/home/bartomeu/Documents/project1/app1/views.py", line 69, in request_process
    f.write(str(file.name))
AttributeError: 'str' object has no attribute 'name'
[30/05/2019 17:04:53] WARNING: Not Found: /favicon.ico
[30/05/2019 17:04:54] ERROR: Internal Server Error: /app1/requestProcess/
Traceback (most recent call last):
  File "/home/bartomeu/djenv/lib/python3.6/site-packages/django/core/handlers/exception.py", line 34, in inner
    response = get_response(request)
  File "/home/bartomeu/djenv/lib/python3.6/site-packages/django/core/handlers/base.py", line 126, in _get_response
    response = self.process_exception_by_middleware(e, request)
  File "/home/bartomeu/djenv/lib/python3.6/site-packages/django/core/handlers/base.py", line 124, in _get_response
    response = wrapped_callback(request, *callback_args, **callback_kwargs)
  File "/home/bartomeu/Documents/project1/app1/views.py", line 71, in request_process
    fs.save(file.name, file)
AttributeError: 'str' object has no attribute 'name'
[30/05/2019 17:05:26] WARNING: Not Found: /app1/requestProcess/home.css
[30/05/2019 17:05:26] WARNING: Not Found: /docs/4.2/dist/js/bootstrap.bundle.min.js
[30/05/2019 17:05:26] WARNING: Not Found: /app1/requestProcess/dashboard.js
[30/05/2019 17:05:26] WARNING: Not Found: /docs/4.2/dist/js/bootstrap.bundle.min.js
[30/05/2019 17:05:26] WARNING: Not Found: /app1/requestProcess/dashboard.js
[30/05/2019 17:16:13] ERROR: Internal Server Error: /app1/requestProcess/
Traceback (most recent call last):
  File "/home/bartomeu/djenv/lib/python3.6/site-packages/django/utils/datastructures.py", line 77, in __getitem__
    list_ = super().__getitem__(key)
KeyError: 'file_field'

During handling of the above exception, another exception occurred:

Traceback (most recent call last):
  File "/home/bartomeu/djenv/lib/python3.6/site-packages/django/core/handlers/exception.py", line 34, in inner
    response = get_response(request)
  File "/home/bartomeu/djenv/lib/python3.6/site-packages/django/core/handlers/base.py", line 126, in _get_response
    response = self.process_exception_by_middleware(e, request)
  File "/home/bartomeu/djenv/lib/python3.6/site-packages/django/core/handlers/base.py", line 124, in _get_response
    response = wrapped_callback(request, *callback_args, **callback_kwargs)
  File "/home/bartomeu/Documents/project1/app1/views.py", line 66, in request_process
    file = request.FILES['file_field']
  File "/home/bartomeu/djenv/lib/python3.6/site-packages/django/utils/datastructures.py", line 79, in __getitem__
    raise MultiValueDictKeyError(key)
django.utils.datastructures.MultiValueDictKeyError: 'file_field'
[30/05/2019 17:16:56] ERROR: Internal Server Error: /app1/requestProcess/
Traceback (most recent call last):
  File "/home/bartomeu/djenv/lib/python3.6/site-packages/django/core/handlers/exception.py", line 34, in inner
    response = get_response(request)
  File "/home/bartomeu/djenv/lib/python3.6/site-packages/django/core/handlers/base.py", line 126, in _get_response
    response = self.process_exception_by_middleware(e, request)
  File "/home/bartomeu/djenv/lib/python3.6/site-packages/django/core/handlers/base.py", line 124, in _get_response
    response = wrapped_callback(request, *callback_args, **callback_kwargs)
  File "/home/bartomeu/Documents/project1/app1/views.py", line 69, in request_process
    f.write(str(file.name))
AttributeError: 'str' object has no attribute 'name'
[30/05/2019 17:17:05] ERROR: Internal Server Error: /app1/requestProcess/
Traceback (most recent call last):
  File "/home/bartomeu/djenv/lib/python3.6/site-packages/django/core/handlers/exception.py", line 34, in inner
    response = get_response(request)
  File "/home/bartomeu/djenv/lib/python3.6/site-packages/django/core/handlers/base.py", line 126, in _get_response
    response = self.process_exception_by_middleware(e, request)
  File "/home/bartomeu/djenv/lib/python3.6/site-packages/django/core/handlers/base.py", line 124, in _get_response
    response = wrapped_callback(request, *callback_args, **callback_kwargs)
  File "/home/bartomeu/Documents/project1/app1/views.py", line 71, in request_process
    fs.save("a", file)
  File "/home/bartomeu/djenv/lib/python3.6/site-packages/django/core/files/storage.py", line 49, in save
    return self._save(name, content)
  File "/home/bartomeu/djenv/lib/python3.6/site-packages/django/core/files/storage.py", line 264, in _save
    fd = os.open(full_path, flags, 0o666)
PermissionError: [Errno 13] Permission denied: '/media/a'
[30/05/2019 17:19:02] ERROR: Internal Server Error: /app1/requestProcess/
Traceback (most recent call last):
  File "/home/bartomeu/djenv/lib/python3.6/site-packages/django/core/handlers/exception.py", line 34, in inner
    response = get_response(request)
  File "/home/bartomeu/djenv/lib/python3.6/site-packages/django/core/handlers/base.py", line 126, in _get_response
    response = self.process_exception_by_middleware(e, request)
  File "/home/bartomeu/djenv/lib/python3.6/site-packages/django/core/handlers/base.py", line 124, in _get_response
    response = wrapped_callback(request, *callback_args, **callback_kwargs)
  File "/home/bartomeu/Documents/project1/app1/views.py", line 71, in request_process
    fs.save("a", file)
  File "/home/bartomeu/djenv/lib/python3.6/site-packages/django/core/files/storage.py", line 49, in save
    return self._save(name, content)
  File "/home/bartomeu/djenv/lib/python3.6/site-packages/django/core/files/storage.py", line 268, in _save
    for chunk in content.chunks():
  File "/home/bartomeu/djenv/lib/python3.6/site-packages/django/core/files/base.py", line 60, in chunks
    data = self.read(chunk_size)
  File "/home/bartomeu/djenv/lib/python3.6/site-packages/django/core/files/utils.py", line 16, in <lambda>
    read = property(lambda self: self.file.read)
AttributeError: 'str' object has no attribute 'read'
[30/05/2019 17:20:18] ERROR: Internal Server Error: /app1/requestProcess/
Traceback (most recent call last):
  File "/home/bartomeu/djenv/lib/python3.6/site-packages/django/core/handlers/exception.py", line 34, in inner
    response = get_response(request)
  File "/home/bartomeu/djenv/lib/python3.6/site-packages/django/core/handlers/base.py", line 126, in _get_response
    response = self.process_exception_by_middleware(e, request)
  File "/home/bartomeu/djenv/lib/python3.6/site-packages/django/core/handlers/base.py", line 124, in _get_response
    response = wrapped_callback(request, *callback_args, **callback_kwargs)
  File "/home/bartomeu/Documents/project1/app1/views.py", line 66, in request_process
    file = form.file_field
AttributeError: 'FileFieldForm' object has no attribute 'file_field'
[30/05/2019 17:20:33] ERROR: Internal Server Error: /app1/requestProcess/
Traceback (most recent call last):
  File "/home/bartomeu/djenv/lib/python3.6/site-packages/django/core/handlers/exception.py", line 34, in inner
    response = get_response(request)
  File "/home/bartomeu/djenv/lib/python3.6/site-packages/django/core/handlers/base.py", line 126, in _get_response
    response = self.process_exception_by_middleware(e, request)
  File "/home/bartomeu/djenv/lib/python3.6/site-packages/django/core/handlers/base.py", line 124, in _get_response
    response = wrapped_callback(request, *callback_args, **callback_kwargs)
  File "/home/bartomeu/Documents/project1/app1/views.py", line 71, in request_process
    fs.save("a", file)
  File "/home/bartomeu/djenv/lib/python3.6/site-packages/django/core/files/storage.py", line 49, in save
    return self._save(name, content)
  File "/home/bartomeu/djenv/lib/python3.6/site-packages/django/core/files/storage.py", line 268, in _save
    for chunk in content.chunks():
  File "/home/bartomeu/djenv/lib/python3.6/site-packages/django/core/files/base.py", line 60, in chunks
    data = self.read(chunk_size)
  File "/home/bartomeu/djenv/lib/python3.6/site-packages/django/core/files/utils.py", line 16, in <lambda>
    read = property(lambda self: self.file.read)
AttributeError: 'BoundField' object has no attribute 'read'
[30/05/2019 17:22:14] ERROR: Internal Server Error: /app1/requestProcess/
Traceback (most recent call last):
  File "/home/bartomeu/djenv/lib/python3.6/site-packages/django/core/handlers/exception.py", line 34, in inner
    response = get_response(request)
  File "/home/bartomeu/djenv/lib/python3.6/site-packages/django/core/handlers/base.py", line 126, in _get_response
    response = self.process_exception_by_middleware(e, request)
  File "/home/bartomeu/djenv/lib/python3.6/site-packages/django/core/handlers/base.py", line 124, in _get_response
    response = wrapped_callback(request, *callback_args, **callback_kwargs)
  File "/home/bartomeu/Documents/project1/app1/views.py", line 71, in request_process
    fs.save("a", file)
  File "/home/bartomeu/djenv/lib/python3.6/site-packages/django/core/files/storage.py", line 49, in save
    return self._save(name, content)
  File "/home/bartomeu/djenv/lib/python3.6/site-packages/django/core/files/storage.py", line 268, in _save
    for chunk in content.chunks():
  File "/home/bartomeu/djenv/lib/python3.6/site-packages/django/core/files/base.py", line 60, in chunks
    data = self.read(chunk_size)
  File "/home/bartomeu/djenv/lib/python3.6/site-packages/django/core/files/utils.py", line 16, in <lambda>
    read = property(lambda self: self.file.read)
AttributeError: 'FileField' object has no attribute 'read'
[30/05/2019 17:22:55] ERROR: Internal Server Error: /app1/requestProcess/
Traceback (most recent call last):
  File "/home/bartomeu/djenv/lib/python3.6/site-packages/django/core/handlers/exception.py", line 34, in inner
    response = get_response(request)
  File "/home/bartomeu/djenv/lib/python3.6/site-packages/django/core/handlers/base.py", line 126, in _get_response
    response = self.process_exception_by_middleware(e, request)
  File "/home/bartomeu/djenv/lib/python3.6/site-packages/django/core/handlers/base.py", line 124, in _get_response
    response = wrapped_callback(request, *callback_args, **callback_kwargs)
  File "/home/bartomeu/Documents/project1/app1/views.py", line 66, in request_process
    file = form['file_field'].field.file
AttributeError: 'FileField' object has no attribute 'file'
[30/05/2019 17:25:08] ERROR: Internal Server Error: /app1/requestProcess/
Traceback (most recent call last):
  File "/home/bartomeu/djenv/lib/python3.6/site-packages/django/core/handlers/exception.py", line 34, in inner
    response = get_response(request)
  File "/home/bartomeu/djenv/lib/python3.6/site-packages/django/core/handlers/base.py", line 126, in _get_response
    response = self.process_exception_by_middleware(e, request)
  File "/home/bartomeu/djenv/lib/python3.6/site-packages/django/core/handlers/base.py", line 124, in _get_response
    response = wrapped_callback(request, *callback_args, **callback_kwargs)
  File "/home/bartomeu/Documents/project1/app1/views.py", line 66, in request_process
    file = form['file_field'].field['file_field']
TypeError: 'FileField' object is not subscriptable
[30/05/2019 17:28:46] WARNING: Not Found: /favicon.ico
[30/05/2019 17:30:08] ERROR: Internal Server Error: /app1/requestProcess/
Traceback (most recent call last):
  File "/home/bartomeu/djenv/lib/python3.6/site-packages/django/core/handlers/exception.py", line 34, in inner
    response = get_response(request)
  File "/home/bartomeu/djenv/lib/python3.6/site-packages/django/core/handlers/base.py", line 126, in _get_response
    response = self.process_exception_by_middleware(e, request)
  File "/home/bartomeu/djenv/lib/python3.6/site-packages/django/core/handlers/base.py", line 124, in _get_response
    response = wrapped_callback(request, *callback_args, **callback_kwargs)
  File "/home/bartomeu/Documents/project1/app1/views.py", line 66, in request_process
    file = form['file_field'].field['file_field']
TypeError: 'FileField' object is not subscriptable
[30/05/2019 17:30:08] WARNING: Not Found: /favicon.ico
[30/05/2019 17:32:07] WARNING: Not Found: /app1/requestProcess/home.css
[30/05/2019 17:32:07] WARNING: Not Found: /docs/4.2/dist/js/bootstrap.bundle.min.js
[30/05/2019 17:32:07] WARNING: Not Found: /app1/requestProcess/dashboard.js
[30/05/2019 17:32:07] WARNING: Not Found: /docs/4.2/dist/js/bootstrap.bundle.min.js
[30/05/2019 17:32:07] WARNING: Not Found: /app1/requestProcess/dashboard.js
[30/05/2019 17:32:07] WARNING: Not Found: /favicon.ico
[30/05/2019 17:33:06] ERROR: Internal Server Error: /app1/requestProcess/
Traceback (most recent call last):
  File "/home/bartomeu/djenv/lib/python3.6/site-packages/django/core/handlers/exception.py", line 34, in inner
    response = get_response(request)
  File "/home/bartomeu/djenv/lib/python3.6/site-packages/django/core/handlers/base.py", line 126, in _get_response
    response = self.process_exception_by_middleware(e, request)
  File "/home/bartomeu/djenv/lib/python3.6/site-packages/django/core/handlers/base.py", line 124, in _get_response
    response = wrapped_callback(request, *callback_args, **callback_kwargs)
  File "/home/bartomeu/Documents/project1/app1/views.py", line 69, in request_process
    fs.save(f.name, f)
AttributeError: 'bytes' object has no attribute 'name'
[30/05/2019 17:33:52] WARNING: Not Found: /docs/4.2/dist/js/bootstrap.bundle.min.js
[30/05/2019 17:33:52] WARNING: Not Found: /app1/requestProcess/dashboard.js
[30/05/2019 17:33:52] WARNING: Not Found: /app1/requestProcess/home.css
[30/05/2019 17:33:52] WARNING: Not Found: /app1/requestProcess/dashboard.js
[30/05/2019 17:33:52] WARNING: Not Found: /favicon.ico
[30/05/2019 17:35:07] ERROR: Internal Server Error: /app1/requestProcess/
Traceback (most recent call last):
  File "/home/bartomeu/djenv/lib/python3.6/site-packages/django/core/handlers/exception.py", line 34, in inner
    response = get_response(request)
  File "/home/bartomeu/djenv/lib/python3.6/site-packages/django/core/handlers/base.py", line 126, in _get_response
    response = self.process_exception_by_middleware(e, request)
  File "/home/bartomeu/djenv/lib/python3.6/site-packages/django/core/handlers/base.py", line 124, in _get_response
    response = wrapped_callback(request, *callback_args, **callback_kwargs)
  File "/home/bartomeu/Documents/project1/app1/views.py", line 68, in request_process
    fs.save(files.name, files)
AttributeError: 'list' object has no attribute 'name'
[30/05/2019 17:35:37] WARNING: Not Found: /docs/4.2/dist/js/bootstrap.bundle.min.js
[30/05/2019 17:35:37] WARNING: Not Found: /app1/requestProcess/dashboard.js
[30/05/2019 17:35:37] WARNING: Not Found: /app1/requestProcess/home.css
[30/05/2019 17:35:37] WARNING: Not Found: /app1/requestProcess/dashboard.js
[30/05/2019 17:51:19] WARNING: Not Found: /app1/requestProcess/home.css
[30/05/2019 17:51:19] WARNING: Not Found: /docs/4.2/dist/js/bootstrap.bundle.min.js
[30/05/2019 17:51:19] WARNING: Not Found: /app1/requestProcess/dashboard.js
[30/05/2019 17:51:19] WARNING: Not Found: /docs/4.2/dist/js/bootstrap.bundle.min.js
[30/05/2019 17:51:19] WARNING: Not Found: /app1/requestProcess/dashboard.js
[30/05/2019 18:12:26] ERROR: Internal Server Error: /app1/requestProcess/
Traceback (most recent call last):
  File "/home/bartomeu/djenv/lib/python3.6/site-packages/django/core/handlers/exception.py", line 34, in inner
    response = get_response(request)
  File "/home/bartomeu/djenv/lib/python3.6/site-packages/django/core/handlers/base.py", line 126, in _get_response
    response = self.process_exception_by_middleware(e, request)
  File "/home/bartomeu/djenv/lib/python3.6/site-packages/django/core/handlers/base.py", line 124, in _get_response
    response = wrapped_callback(request, *callback_args, **callback_kwargs)
  File "/home/bartomeu/Documents/project1/app1/views.py", line 68, in request_process
    if form.is_valid():
AttributeError: 'QueryDict' object has no attribute 'is_valid'
[30/05/2019 18:13:03] ERROR: Internal Server Error: /app1/requestProcess/
Traceback (most recent call last):
  File "/home/bartomeu/djenv/lib/python3.6/site-packages/django/core/handlers/exception.py", line 34, in inner
    response = get_response(request)
  File "/home/bartomeu/djenv/lib/python3.6/site-packages/django/core/handlers/base.py", line 126, in _get_response
    response = self.process_exception_by_middleware(e, request)
  File "/home/bartomeu/djenv/lib/python3.6/site-packages/django/core/handlers/base.py", line 124, in _get_response
    response = wrapped_callback(request, *callback_args, **callback_kwargs)
  File "/home/bartomeu/Documents/project1/app1/views.py", line 68, in request_process
    type_of_process = form.cleaned_data['files']
AttributeError: 'QueryDict' object has no attribute 'cleaned_data'
[30/05/2019 18:14:13] ERROR: Internal Server Error: /app1/requestProcess/
Traceback (most recent call last):
  File "/home/bartomeu/djenv/lib/python3.6/site-packages/django/db/backends/utils.py", line 85, in _execute
    return self.cursor.execute(sql, params)
  File "/home/bartomeu/djenv/lib/python3.6/site-packages/django/db/backends/sqlite3/base.py", line 296, in execute
    return Database.Cursor.execute(self, query, params)
sqlite3.IntegrityError: NOT NULL constraint failed: app1_request.date_of_start

The above exception was the direct cause of the following exception:

Traceback (most recent call last):
  File "/home/bartomeu/djenv/lib/python3.6/site-packages/django/core/handlers/exception.py", line 34, in inner
    response = get_response(request)
  File "/home/bartomeu/djenv/lib/python3.6/site-packages/django/core/handlers/base.py", line 126, in _get_response
    response = self.process_exception_by_middleware(e, request)
  File "/home/bartomeu/djenv/lib/python3.6/site-packages/django/core/handlers/base.py", line 124, in _get_response
    response = wrapped_callback(request, *callback_args, **callback_kwargs)
  File "/home/bartomeu/Documents/project1/app1/views.py", line 77, in request_process
    r.save()
  File "/home/bartomeu/djenv/lib/python3.6/site-packages/django/db/models/base.py", line 718, in save
    force_update=force_update, update_fields=update_fields)
  File "/home/bartomeu/djenv/lib/python3.6/site-packages/django/db/models/base.py", line 748, in save_base
    updated = self._save_table(raw, cls, force_insert, force_update, using, update_fields)
  File "/home/bartomeu/djenv/lib/python3.6/site-packages/django/db/models/base.py", line 831, in _save_table
    result = self._do_insert(cls._base_manager, using, fields, update_pk, raw)
  File "/home/bartomeu/djenv/lib/python3.6/site-packages/django/db/models/base.py", line 869, in _do_insert
    using=using, raw=raw)
  File "/home/bartomeu/djenv/lib/python3.6/site-packages/django/db/models/manager.py", line 82, in manager_method
    return getattr(self.get_queryset(), name)(*args, **kwargs)
  File "/home/bartomeu/djenv/lib/python3.6/site-packages/django/db/models/query.py", line 1136, in _insert
    return query.get_compiler(using=using).execute_sql(return_id)
  File "/home/bartomeu/djenv/lib/python3.6/site-packages/django/db/models/sql/compiler.py", line 1289, in execute_sql
    cursor.execute(sql, params)
  File "/home/bartomeu/djenv/lib/python3.6/site-packages/django/db/backends/utils.py", line 100, in execute
    return super().execute(sql, params)
  File "/home/bartomeu/djenv/lib/python3.6/site-packages/django/db/backends/utils.py", line 68, in execute
    return self._execute_with_wrappers(sql, params, many=False, executor=self._execute)
  File "/home/bartomeu/djenv/lib/python3.6/site-packages/django/db/backends/utils.py", line 77, in _execute_with_wrappers
    return executor(sql, params, many, context)
  File "/home/bartomeu/djenv/lib/python3.6/site-packages/django/db/backends/utils.py", line 85, in _execute
    return self.cursor.execute(sql, params)
  File "/home/bartomeu/djenv/lib/python3.6/site-packages/django/db/utils.py", line 89, in __exit__
    raise dj_exc_value.with_traceback(traceback) from exc_value
  File "/home/bartomeu/djenv/lib/python3.6/site-packages/django/db/backends/utils.py", line 85, in _execute
    return self.cursor.execute(sql, params)
  File "/home/bartomeu/djenv/lib/python3.6/site-packages/django/db/backends/sqlite3/base.py", line 296, in execute
    return Database.Cursor.execute(self, query, params)
django.db.utils.IntegrityError: NOT NULL constraint failed: app1_request.date_of_start
[30/05/2019 18:14:34] ERROR: Internal Server Error: /app1/requestProcess/
Traceback (most recent call last):
  File "/home/bartomeu/djenv/lib/python3.6/site-packages/django/db/backends/utils.py", line 85, in _execute
    return self.cursor.execute(sql, params)
  File "/home/bartomeu/djenv/lib/python3.6/site-packages/django/db/backends/sqlite3/base.py", line 296, in execute
    return Database.Cursor.execute(self, query, params)
sqlite3.IntegrityError: NOT NULL constraint failed: app1_request.date_of_start

The above exception was the direct cause of the following exception:

Traceback (most recent call last):
  File "/home/bartomeu/djenv/lib/python3.6/site-packages/django/core/handlers/exception.py", line 34, in inner
    response = get_response(request)
  File "/home/bartomeu/djenv/lib/python3.6/site-packages/django/core/handlers/base.py", line 126, in _get_response
    response = self.process_exception_by_middleware(e, request)
  File "/home/bartomeu/djenv/lib/python3.6/site-packages/django/core/handlers/base.py", line 124, in _get_response
    response = wrapped_callback(request, *callback_args, **callback_kwargs)
  File "/home/bartomeu/Documents/project1/app1/views.py", line 77, in request_process
    r.save()
  File "/home/bartomeu/djenv/lib/python3.6/site-packages/django/db/models/base.py", line 718, in save
    force_update=force_update, update_fields=update_fields)
  File "/home/bartomeu/djenv/lib/python3.6/site-packages/django/db/models/base.py", line 748, in save_base
    updated = self._save_table(raw, cls, force_insert, force_update, using, update_fields)
  File "/home/bartomeu/djenv/lib/python3.6/site-packages/django/db/models/base.py", line 831, in _save_table
    result = self._do_insert(cls._base_manager, using, fields, update_pk, raw)
  File "/home/bartomeu/djenv/lib/python3.6/site-packages/django/db/models/base.py", line 869, in _do_insert
    using=using, raw=raw)
  File "/home/bartomeu/djenv/lib/python3.6/site-packages/django/db/models/manager.py", line 82, in manager_method
    return getattr(self.get_queryset(), name)(*args, **kwargs)
  File "/home/bartomeu/djenv/lib/python3.6/site-packages/django/db/models/query.py", line 1136, in _insert
    return query.get_compiler(using=using).execute_sql(return_id)
  File "/home/bartomeu/djenv/lib/python3.6/site-packages/django/db/models/sql/compiler.py", line 1289, in execute_sql
    cursor.execute(sql, params)
  File "/home/bartomeu/djenv/lib/python3.6/site-packages/django/db/backends/utils.py", line 100, in execute
    return super().execute(sql, params)
  File "/home/bartomeu/djenv/lib/python3.6/site-packages/django/db/backends/utils.py", line 68, in execute
    return self._execute_with_wrappers(sql, params, many=False, executor=self._execute)
  File "/home/bartomeu/djenv/lib/python3.6/site-packages/django/db/backends/utils.py", line 77, in _execute_with_wrappers
    return executor(sql, params, many, context)
  File "/home/bartomeu/djenv/lib/python3.6/site-packages/django/db/backends/utils.py", line 85, in _execute
    return self.cursor.execute(sql, params)
  File "/home/bartomeu/djenv/lib/python3.6/site-packages/django/db/utils.py", line 89, in __exit__
    raise dj_exc_value.with_traceback(traceback) from exc_value
  File "/home/bartomeu/djenv/lib/python3.6/site-packages/django/db/backends/utils.py", line 85, in _execute
    return self.cursor.execute(sql, params)
  File "/home/bartomeu/djenv/lib/python3.6/site-packages/django/db/backends/sqlite3/base.py", line 296, in execute
    return Database.Cursor.execute(self, query, params)
django.db.utils.IntegrityError: NOT NULL constraint failed: app1_request.date_of_start
[30/05/2019 18:40:52] INFO: User: admin has logged in.
[30/05/2019 18:40:52] WARNING: Not Found: /app1/login/home.css
[30/05/2019 18:40:52] WARNING: Not Found: /docs/4.2/dist/js/bootstrap.bundle.min.js
[30/05/2019 18:40:52] WARNING: Not Found: /app1/login/dashboard.js
[30/05/2019 18:40:52] WARNING: Not Found: /app1/login/dashboard.js
[30/05/2019 18:41:03] ERROR: Internal Server Error: /app1/requestProcess/
Traceback (most recent call last):
  File "/home/bartomeu/djenv/lib/python3.6/site-packages/django/core/handlers/exception.py", line 34, in inner
    response = get_response(request)
  File "/home/bartomeu/djenv/lib/python3.6/site-packages/django/core/handlers/base.py", line 126, in _get_response
    response = self.process_exception_by_middleware(e, request)
  File "/home/bartomeu/djenv/lib/python3.6/site-packages/django/core/handlers/base.py", line 124, in _get_response
    response = wrapped_callback(request, *callback_args, **callback_kwargs)
  File "/home/bartomeu/Documents/project1/app1/views.py", line 77, in request_process
    r.save()
  File "/home/bartomeu/djenv/lib/python3.6/site-packages/django/db/models/base.py", line 718, in save
    force_update=force_update, update_fields=update_fields)
  File "/home/bartomeu/djenv/lib/python3.6/site-packages/django/db/models/base.py", line 748, in save_base
    updated = self._save_table(raw, cls, force_insert, force_update, using, update_fields)
  File "/home/bartomeu/djenv/lib/python3.6/site-packages/django/db/models/base.py", line 831, in _save_table
    result = self._do_insert(cls._base_manager, using, fields, update_pk, raw)
  File "/home/bartomeu/djenv/lib/python3.6/site-packages/django/db/models/base.py", line 869, in _do_insert
    using=using, raw=raw)
  File "/home/bartomeu/djenv/lib/python3.6/site-packages/django/db/models/manager.py", line 82, in manager_method
    return getattr(self.get_queryset(), name)(*args, **kwargs)
  File "/home/bartomeu/djenv/lib/python3.6/site-packages/django/db/models/query.py", line 1136, in _insert
    return query.get_compiler(using=using).execute_sql(return_id)
  File "/home/bartomeu/djenv/lib/python3.6/site-packages/django/db/models/sql/compiler.py", line 1288, in execute_sql
    for sql, params in self.as_sql():
  File "/home/bartomeu/djenv/lib/python3.6/site-packages/django/db/models/sql/compiler.py", line 1241, in as_sql
    for obj in self.query.objs
  File "/home/bartomeu/djenv/lib/python3.6/site-packages/django/db/models/sql/compiler.py", line 1241, in <listcomp>
    for obj in self.query.objs
  File "/home/bartomeu/djenv/lib/python3.6/site-packages/django/db/models/sql/compiler.py", line 1240, in <listcomp>
    [self.prepare_value(field, self.pre_save_val(field, obj)) for field in fields]
  File "/home/bartomeu/djenv/lib/python3.6/site-packages/django/db/models/sql/compiler.py", line 1182, in prepare_value
    value = field.get_db_prep_save(value, connection=self.connection)
  File "/home/bartomeu/djenv/lib/python3.6/site-packages/django/db/models/fields/__init__.py", line 790, in get_db_prep_save
    return self.get_db_prep_value(value, connection=connection, prepared=False)
  File "/home/bartomeu/djenv/lib/python3.6/site-packages/django/db/models/fields/__init__.py", line 1429, in get_db_prep_value
    value = self.get_prep_value(value)
  File "/home/bartomeu/djenv/lib/python3.6/site-packages/django/db/models/fields/__init__.py", line 1408, in get_prep_value
    value = super().get_prep_value(value)
  File "/home/bartomeu/djenv/lib/python3.6/site-packages/django/db/models/fields/__init__.py", line 1268, in get_prep_value
    return self.to_python(value)
  File "/home/bartomeu/djenv/lib/python3.6/site-packages/django/db/models/fields/__init__.py", line 1369, in to_python
    parsed = parse_datetime(value)
  File "/home/bartomeu/djenv/lib/python3.6/site-packages/django/utils/dateparse.py", line 106, in parse_datetime
    match = datetime_re.match(value)
TypeError: expected string or bytes-like object
[30/05/2019 18:46:25] ERROR: Internal Server Error: /app1/requestProcess/
Traceback (most recent call last):
  File "/home/bartomeu/djenv/lib/python3.6/site-packages/django/core/handlers/exception.py", line 34, in inner
    response = get_response(request)
  File "/home/bartomeu/djenv/lib/python3.6/site-packages/django/core/handlers/base.py", line 126, in _get_response
    response = self.process_exception_by_middleware(e, request)
  File "/home/bartomeu/djenv/lib/python3.6/site-packages/django/core/handlers/base.py", line 124, in _get_response
    response = wrapped_callback(request, *callback_args, **callback_kwargs)
  File "/home/bartomeu/Documents/project1/app1/views.py", line 76, in request_process
    user=user))
  File "/home/bartomeu/Documents/project1/app1/models.py", line 34, in __str__
    ', by: ' + str(self.user) + ', time: ' + str(self.time)
AttributeError: 'Request' object has no attribute 'topology'
[30/05/2019 19:03:04] ERROR: Internal Server Error: /app1/requestProcess/
Traceback (most recent call last):
  File "/home/bartomeu/djenv/lib/python3.6/site-packages/django/core/handlers/exception.py", line 34, in inner
    response = get_response(request)
  File "/home/bartomeu/djenv/lib/python3.6/site-packages/django/core/handlers/base.py", line 126, in _get_response
    response = self.process_exception_by_middleware(e, request)
  File "/home/bartomeu/djenv/lib/python3.6/site-packages/django/core/handlers/base.py", line 124, in _get_response
    response = wrapped_callback(request, *callback_args, **callback_kwargs)
  File "/home/bartomeu/Documents/project1/app1/views.py", line 76, in request_process
    user=user))
TypeError: __str__ returned non-string (type tuple)
[30/05/2019 19:04:14] ERROR: Internal Server Error: /app1/requestProcess/
Traceback (most recent call last):
  File "/home/bartomeu/djenv/lib/python3.6/site-packages/django/core/handlers/exception.py", line 34, in inner
    response = get_response(request)
  File "/home/bartomeu/djenv/lib/python3.6/site-packages/django/core/handlers/base.py", line 126, in _get_response
    response = self.process_exception_by_middleware(e, request)
  File "/home/bartomeu/djenv/lib/python3.6/site-packages/django/core/handlers/base.py", line 124, in _get_response
    response = wrapped_callback(request, *callback_args, **callback_kwargs)
  File "/home/bartomeu/Documents/project1/app1/views.py", line 76, in request_process
    user=user)).save()
  File "/home/bartomeu/djenv/lib/python3.6/site-packages/django/db/models/base.py", line 718, in save
    force_update=force_update, update_fields=update_fields)
  File "/home/bartomeu/djenv/lib/python3.6/site-packages/django/db/models/base.py", line 748, in save_base
    updated = self._save_table(raw, cls, force_insert, force_update, using, update_fields)
  File "/home/bartomeu/djenv/lib/python3.6/site-packages/django/db/models/base.py", line 831, in _save_table
    result = self._do_insert(cls._base_manager, using, fields, update_pk, raw)
  File "/home/bartomeu/djenv/lib/python3.6/site-packages/django/db/models/base.py", line 869, in _do_insert
    using=using, raw=raw)
  File "/home/bartomeu/djenv/lib/python3.6/site-packages/django/db/models/manager.py", line 82, in manager_method
    return getattr(self.get_queryset(), name)(*args, **kwargs)
  File "/home/bartomeu/djenv/lib/python3.6/site-packages/django/db/models/query.py", line 1136, in _insert
    return query.get_compiler(using=using).execute_sql(return_id)
  File "/home/bartomeu/djenv/lib/python3.6/site-packages/django/db/models/sql/compiler.py", line 1288, in execute_sql
    for sql, params in self.as_sql():
  File "/home/bartomeu/djenv/lib/python3.6/site-packages/django/db/models/sql/compiler.py", line 1241, in as_sql
    for obj in self.query.objs
  File "/home/bartomeu/djenv/lib/python3.6/site-packages/django/db/models/sql/compiler.py", line 1241, in <listcomp>
    for obj in self.query.objs
  File "/home/bartomeu/djenv/lib/python3.6/site-packages/django/db/models/sql/compiler.py", line 1240, in <listcomp>
    [self.prepare_value(field, self.pre_save_val(field, obj)) for field in fields]
  File "/home/bartomeu/djenv/lib/python3.6/site-packages/django/db/models/sql/compiler.py", line 1182, in prepare_value
    value = field.get_db_prep_save(value, connection=self.connection)
  File "/home/bartomeu/djenv/lib/python3.6/site-packages/django/db/models/fields/__init__.py", line 790, in get_db_prep_save
    return self.get_db_prep_value(value, connection=connection, prepared=False)
  File "/home/bartomeu/djenv/lib/python3.6/site-packages/django/db/models/fields/__init__.py", line 1429, in get_db_prep_value
    value = self.get_prep_value(value)
  File "/home/bartomeu/djenv/lib/python3.6/site-packages/django/db/models/fields/__init__.py", line 1408, in get_prep_value
    value = super().get_prep_value(value)
  File "/home/bartomeu/djenv/lib/python3.6/site-packages/django/db/models/fields/__init__.py", line 1268, in get_prep_value
    return self.to_python(value)
  File "/home/bartomeu/djenv/lib/python3.6/site-packages/django/db/models/fields/__init__.py", line 1369, in to_python
    parsed = parse_datetime(value)
  File "/home/bartomeu/djenv/lib/python3.6/site-packages/django/utils/dateparse.py", line 106, in parse_datetime
    match = datetime_re.match(value)
TypeError: expected string or bytes-like object
[30/05/2019 19:06:42] ERROR: Internal Server Error: /app1/requestProcess/
Traceback (most recent call last):
  File "/home/bartomeu/djenv/lib/python3.6/site-packages/django/core/handlers/exception.py", line 34, in inner
    response = get_response(request)
  File "/home/bartomeu/djenv/lib/python3.6/site-packages/django/core/handlers/base.py", line 126, in _get_response
    response = self.process_exception_by_middleware(e, request)
  File "/home/bartomeu/djenv/lib/python3.6/site-packages/django/core/handlers/base.py", line 124, in _get_response
    response = wrapped_callback(request, *callback_args, **callback_kwargs)
  File "/home/bartomeu/Documents/project1/app1/views.py", line 76, in request_process
    r.save()
  File "/home/bartomeu/djenv/lib/python3.6/site-packages/django/db/models/base.py", line 718, in save
    force_update=force_update, update_fields=update_fields)
  File "/home/bartomeu/djenv/lib/python3.6/site-packages/django/db/models/base.py", line 748, in save_base
    updated = self._save_table(raw, cls, force_insert, force_update, using, update_fields)
  File "/home/bartomeu/djenv/lib/python3.6/site-packages/django/db/models/base.py", line 831, in _save_table
    result = self._do_insert(cls._base_manager, using, fields, update_pk, raw)
  File "/home/bartomeu/djenv/lib/python3.6/site-packages/django/db/models/base.py", line 869, in _do_insert
    using=using, raw=raw)
  File "/home/bartomeu/djenv/lib/python3.6/site-packages/django/db/models/manager.py", line 82, in manager_method
    return getattr(self.get_queryset(), name)(*args, **kwargs)
  File "/home/bartomeu/djenv/lib/python3.6/site-packages/django/db/models/query.py", line 1136, in _insert
    return query.get_compiler(using=using).execute_sql(return_id)
  File "/home/bartomeu/djenv/lib/python3.6/site-packages/django/db/models/sql/compiler.py", line 1288, in execute_sql
    for sql, params in self.as_sql():
  File "/home/bartomeu/djenv/lib/python3.6/site-packages/django/db/models/sql/compiler.py", line 1241, in as_sql
    for obj in self.query.objs
  File "/home/bartomeu/djenv/lib/python3.6/site-packages/django/db/models/sql/compiler.py", line 1241, in <listcomp>
    for obj in self.query.objs
  File "/home/bartomeu/djenv/lib/python3.6/site-packages/django/db/models/sql/compiler.py", line 1240, in <listcomp>
    [self.prepare_value(field, self.pre_save_val(field, obj)) for field in fields]
  File "/home/bartomeu/djenv/lib/python3.6/site-packages/django/db/models/sql/compiler.py", line 1182, in prepare_value
    value = field.get_db_prep_save(value, connection=self.connection)
  File "/home/bartomeu/djenv/lib/python3.6/site-packages/django/db/models/fields/__init__.py", line 790, in get_db_prep_save
    return self.get_db_prep_value(value, connection=connection, prepared=False)
  File "/home/bartomeu/djenv/lib/python3.6/site-packages/django/db/models/fields/__init__.py", line 1429, in get_db_prep_value
    value = self.get_prep_value(value)
  File "/home/bartomeu/djenv/lib/python3.6/site-packages/django/db/models/fields/__init__.py", line 1408, in get_prep_value
    value = super().get_prep_value(value)
  File "/home/bartomeu/djenv/lib/python3.6/site-packages/django/db/models/fields/__init__.py", line 1268, in get_prep_value
    return self.to_python(value)
  File "/home/bartomeu/djenv/lib/python3.6/site-packages/django/db/models/fields/__init__.py", line 1369, in to_python
    parsed = parse_datetime(value)
  File "/home/bartomeu/djenv/lib/python3.6/site-packages/django/utils/dateparse.py", line 106, in parse_datetime
    match = datetime_re.match(value)
TypeError: expected string or bytes-like object
[30/05/2019 19:07:43] ERROR: Internal Server Error: /app1/requestProcess/
Traceback (most recent call last):
  File "/home/bartomeu/djenv/lib/python3.6/site-packages/django/core/handlers/exception.py", line 34, in inner
    response = get_response(request)
  File "/home/bartomeu/djenv/lib/python3.6/site-packages/django/core/handlers/base.py", line 126, in _get_response
    response = self.process_exception_by_middleware(e, request)
  File "/home/bartomeu/djenv/lib/python3.6/site-packages/django/core/handlers/base.py", line 124, in _get_response
    response = wrapped_callback(request, *callback_args, **callback_kwargs)
  File "/home/bartomeu/Documents/project1/app1/views.py", line 75, in request_process
    user=str(user))
  File "/home/bartomeu/djenv/lib/python3.6/site-packages/django/db/models/base.py", line 467, in __init__
    _setattr(self, field.name, rel_obj)
  File "/home/bartomeu/djenv/lib/python3.6/site-packages/django/db/models/fields/related_descriptors.py", line 210, in __set__
    self.field.remote_field.model._meta.object_name,
ValueError: Cannot assign "'admin'": "Request.user" must be a "User" instance.
[30/05/2019 19:09:16] ERROR: Internal Server Error: /app1/requestProcess/
Traceback (most recent call last):
  File "/home/bartomeu/djenv/lib/python3.6/site-packages/django/core/handlers/exception.py", line 34, in inner
    response = get_response(request)
  File "/home/bartomeu/djenv/lib/python3.6/site-packages/django/core/handlers/base.py", line 126, in _get_response
    response = self.process_exception_by_middleware(e, request)
  File "/home/bartomeu/djenv/lib/python3.6/site-packages/django/core/handlers/base.py", line 124, in _get_response
    response = wrapped_callback(request, *callback_args, **callback_kwargs)
  File "/home/bartomeu/Documents/project1/app1/views.py", line 76, in request_process
    r.save()
  File "/home/bartomeu/djenv/lib/python3.6/site-packages/django/db/models/base.py", line 718, in save
    force_update=force_update, update_fields=update_fields)
  File "/home/bartomeu/djenv/lib/python3.6/site-packages/django/db/models/base.py", line 748, in save_base
    updated = self._save_table(raw, cls, force_insert, force_update, using, update_fields)
  File "/home/bartomeu/djenv/lib/python3.6/site-packages/django/db/models/base.py", line 831, in _save_table
    result = self._do_insert(cls._base_manager, using, fields, update_pk, raw)
  File "/home/bartomeu/djenv/lib/python3.6/site-packages/django/db/models/base.py", line 869, in _do_insert
    using=using, raw=raw)
  File "/home/bartomeu/djenv/lib/python3.6/site-packages/django/db/models/manager.py", line 82, in manager_method
    return getattr(self.get_queryset(), name)(*args, **kwargs)
  File "/home/bartomeu/djenv/lib/python3.6/site-packages/django/db/models/query.py", line 1136, in _insert
    return query.get_compiler(using=using).execute_sql(return_id)
  File "/home/bartomeu/djenv/lib/python3.6/site-packages/django/db/models/sql/compiler.py", line 1288, in execute_sql
    for sql, params in self.as_sql():
  File "/home/bartomeu/djenv/lib/python3.6/site-packages/django/db/models/sql/compiler.py", line 1241, in as_sql
    for obj in self.query.objs
  File "/home/bartomeu/djenv/lib/python3.6/site-packages/django/db/models/sql/compiler.py", line 1241, in <listcomp>
    for obj in self.query.objs
  File "/home/bartomeu/djenv/lib/python3.6/site-packages/django/db/models/sql/compiler.py", line 1240, in <listcomp>
    [self.prepare_value(field, self.pre_save_val(field, obj)) for field in fields]
  File "/home/bartomeu/djenv/lib/python3.6/site-packages/django/db/models/sql/compiler.py", line 1182, in prepare_value
    value = field.get_db_prep_save(value, connection=self.connection)
  File "/home/bartomeu/djenv/lib/python3.6/site-packages/django/db/models/fields/__init__.py", line 790, in get_db_prep_save
    return self.get_db_prep_value(value, connection=connection, prepared=False)
  File "/home/bartomeu/djenv/lib/python3.6/site-packages/django/db/models/fields/__init__.py", line 1429, in get_db_prep_value
    value = self.get_prep_value(value)
  File "/home/bartomeu/djenv/lib/python3.6/site-packages/django/db/models/fields/__init__.py", line 1408, in get_prep_value
    value = super().get_prep_value(value)
  File "/home/bartomeu/djenv/lib/python3.6/site-packages/django/db/models/fields/__init__.py", line 1268, in get_prep_value
    return self.to_python(value)
  File "/home/bartomeu/djenv/lib/python3.6/site-packages/django/db/models/fields/__init__.py", line 1369, in to_python
    parsed = parse_datetime(value)
  File "/home/bartomeu/djenv/lib/python3.6/site-packages/django/utils/dateparse.py", line 106, in parse_datetime
    match = datetime_re.match(value)
TypeError: expected string or bytes-like object
[30/05/2019 19:13:31] ERROR: Internal Server Error: /app1/requestProcess/
Traceback (most recent call last):
  File "/home/bartomeu/djenv/lib/python3.6/site-packages/django/core/handlers/exception.py", line 34, in inner
    response = get_response(request)
  File "/home/bartomeu/djenv/lib/python3.6/site-packages/django/core/handlers/base.py", line 126, in _get_response
    response = self.process_exception_by_middleware(e, request)
  File "/home/bartomeu/djenv/lib/python3.6/site-packages/django/core/handlers/base.py", line 124, in _get_response
    response = wrapped_callback(request, *callback_args, **callback_kwargs)
  File "/home/bartomeu/Documents/project1/app1/views.py", line 76, in request_process
    r.save()
  File "/home/bartomeu/djenv/lib/python3.6/site-packages/django/db/models/base.py", line 718, in save
    force_update=force_update, update_fields=update_fields)
  File "/home/bartomeu/djenv/lib/python3.6/site-packages/django/db/models/base.py", line 748, in save_base
    updated = self._save_table(raw, cls, force_insert, force_update, using, update_fields)
  File "/home/bartomeu/djenv/lib/python3.6/site-packages/django/db/models/base.py", line 831, in _save_table
    result = self._do_insert(cls._base_manager, using, fields, update_pk, raw)
  File "/home/bartomeu/djenv/lib/python3.6/site-packages/django/db/models/base.py", line 869, in _do_insert
    using=using, raw=raw)
  File "/home/bartomeu/djenv/lib/python3.6/site-packages/django/db/models/manager.py", line 82, in manager_method
    return getattr(self.get_queryset(), name)(*args, **kwargs)
  File "/home/bartomeu/djenv/lib/python3.6/site-packages/django/db/models/query.py", line 1136, in _insert
    return query.get_compiler(using=using).execute_sql(return_id)
  File "/home/bartomeu/djenv/lib/python3.6/site-packages/django/db/models/sql/compiler.py", line 1288, in execute_sql
    for sql, params in self.as_sql():
  File "/home/bartomeu/djenv/lib/python3.6/site-packages/django/db/models/sql/compiler.py", line 1241, in as_sql
    for obj in self.query.objs
  File "/home/bartomeu/djenv/lib/python3.6/site-packages/django/db/models/sql/compiler.py", line 1241, in <listcomp>
    for obj in self.query.objs
  File "/home/bartomeu/djenv/lib/python3.6/site-packages/django/db/models/sql/compiler.py", line 1240, in <listcomp>
    [self.prepare_value(field, self.pre_save_val(field, obj)) for field in fields]
  File "/home/bartomeu/djenv/lib/python3.6/site-packages/django/db/models/sql/compiler.py", line 1182, in prepare_value
    value = field.get_db_prep_save(value, connection=self.connection)
  File "/home/bartomeu/djenv/lib/python3.6/site-packages/django/db/models/fields/__init__.py", line 790, in get_db_prep_save
    return self.get_db_prep_value(value, connection=connection, prepared=False)
  File "/home/bartomeu/djenv/lib/python3.6/site-packages/django/db/models/fields/__init__.py", line 1429, in get_db_prep_value
    value = self.get_prep_value(value)
  File "/home/bartomeu/djenv/lib/python3.6/site-packages/django/db/models/fields/__init__.py", line 1408, in get_prep_value
    value = super().get_prep_value(value)
  File "/home/bartomeu/djenv/lib/python3.6/site-packages/django/db/models/fields/__init__.py", line 1268, in get_prep_value
    return self.to_python(value)
  File "/home/bartomeu/djenv/lib/python3.6/site-packages/django/db/models/fields/__init__.py", line 1369, in to_python
    parsed = parse_datetime(value)
  File "/home/bartomeu/djenv/lib/python3.6/site-packages/django/utils/dateparse.py", line 106, in parse_datetime
    match = datetime_re.match(value)
TypeError: expected string or bytes-like object
[30/05/2019 19:14:06] ERROR: Internal Server Error: /app1/requestProcess/
Traceback (most recent call last):
  File "/home/bartomeu/djenv/lib/python3.6/site-packages/django/core/handlers/exception.py", line 34, in inner
    response = get_response(request)
  File "/home/bartomeu/djenv/lib/python3.6/site-packages/django/core/handlers/base.py", line 126, in _get_response
    response = self.process_exception_by_middleware(e, request)
  File "/home/bartomeu/djenv/lib/python3.6/site-packages/django/core/handlers/base.py", line 124, in _get_response
    response = wrapped_callback(request, *callback_args, **callback_kwargs)
  File "/home/bartomeu/Documents/project1/app1/views.py", line 66, in request_process
    user.validate()
AttributeError: 'User' object has no attribute 'validate'
